Workbook

Sheet EDT
A2: Matriz Estructura de descomposición de tareas EDT
A4: Etapas | B4: DIAS | C4: HORAS POR ACTIVIDAD O ENTREGABLE | I4: DICCIONARIO EDT
A5: Fase de Planificación | C5: Jefe de Proyecto | D5: Analista Programador | E5: DBA | F5: QA | G5: Diseñador | I5: ROL ACTOR | J5: NOMBRE ACTOR
A6: Acta de Constitución de proyecto | B6: 5 | C6: 16 | D6: 4 | E6: 2 | F6: 2 | G6: 2 | I6: Jefe de Proyecto | J6: Melisa Quezada
A7: Aprobación del Acta | B7: 2 | C7: 4 | D7: 1 | E7: 1 | F7: 1 | G7: 1 | I7: Analista Programador | J7: Erick Paredes / Daniel Lizama
A8: Definición de requerimientos Generales | B8: 5 | C8: 12 | D8: 10 | E8: 4 | F8: 6 | G8: 4 | I8: DBA | J8: José Miguel Ruíz
A9: Organización del equipo | B9: 2 | C9: 6 | D9: 2 | E9: 2 | F9: 2 | G9: 2 | I9: QA | J9: Cristian Bernal
I10: Diseñador | J10: Fernanda Aliaga
A11: Fase de Análisis y diseño | C11: Jefe de Proyecto | D11: Analista Programador | E11: DBA | F11: QA | G11: Diseñador
A12: Captura de requerimientos específicos | B12: 6 | C12: 12 | D12: 16 | E12: 8 | F12: 8 | G12: 8
A13: Documento de arquitectura SW | B13: 5 | C13: 0 | D13: 0 | E13: 32 | F13: 14 | G13: 0
A14: Documento de casos de uso | B14: 5 | C14: 8 | D14: 16 | E14: 4 | F14: 10 | G14: 4
A15: Prototipos | B15: 8 | C15: 18 | D15: 28 | E15: 0 | F15: 0 | G15: 0
A16: Propuesta ERS | B16: 5 | C16: 14 | D16: 10 | E16: 6 | F16: 6 | G16: 4
A18: Fase de Desarrollo | C18: Jefe de Proyecto | D18: Analista Programador | E18: DBA | F18: QA | G18: Diseñador
A19: Implementación ambiente de desarrollo | B19: 3 | C19: 2 | D19: 12 | E19: 6 | F19: 4 | G19: 0
A20: Creación de los script de tablas base de datos | B20: 5 | C20: 2 | D20: 6 | E20: 28 | F20: 2 | G20: 0
A21: Creación de los script de consultas y funciones PL/pgSQL | B21: 5 | C21: 2 | D21: 8 | E21: 24 | F21: 4 | G21: 0
A22: Módulo de Autenticación y Seguridad
A23: Login, registro y recuperación de contraseña | B23: 4 | C23: 1 | D23: 20 | E23: 4 | F23: 6 | G23: 4
A24: Administración de roles y permisos | B24: 4 | C24: 1 | D24: 18 | E24: 4 | F24: 6 | G24: 3
A26: Módulo de Configuración del Negocio
A27: Perfil del negocio y página pública de reservas | B27: 3 | C27: 1 | D27: 14 | E27: 3 | F27: 4 | G27: 8
A28: Catálogo de servicios y atributos parametrizables | B28: 6 | C28: 2 | D28: 28 | E28: 8 | F28: 8 | G28: 6
A29: Administración de recursos y horarios de atención | B29: 5 | C29: 1 | D29: 22 | E29: 6 | F29: 6 | G29: 5
A31: Módulo de Agenda y Reservas
A32: Motor de disponibilidad multi-recurso | B32: 8 | C32: 2 | D32: 40 | E32: 12 | F32: 12 | G32: 2
A33: Gestión de citas: crear, cancelar y reagendar | B33: 6 | C33: 2 | D33: 26 | E33: 6 | F33: 10 | G33: 4
A34: Vista de calendario por recurso | B34: 5 | C34: 1 | D34: 20 | E34: 3 | F34: 6 | G34: 10
A35: Ficha e historial del cliente | B35: 4 | C35: 1 | D35: 16 | E35: 5 | F35: 5 | G35: 3
A37: Módulo Portal del Cliente
A38: Reserva desde la página pública | B38: 6 | C38: 2 | D38: 26 | E38: 5 | F38: 8 | G38: 12
A39: Mis servicios agendados y mi calendario | B39: 4 | C39: 1 | D39: 16 | E39: 3 | F39: 5 | G39: 6
A40: Integración con pasarela de pagos | B40: 6 | C40: 2 | D40: 24 | E40: 4 | F40: 8 | G40: 3
A42: Módulo de Inventario e Insumos
A43: Administración de insumos y proveedores | B43: 5 | C43: 1 | D43: 20 | E43: 6 | F43: 6 | G43: 4
A44: Consumo automático de insumos por servicio | B44: 6 | C44: 2 | D44: 24 | E44: 8 | F44: 10 | G44: 2
A46: Módulo de Notificaciones
A47: Recordatorios automáticos de citas | B47: 5 | C47: 1 | D47: 20 | E47: 4 | F47: 6 | G47: 2
A48: Alertas de stock bajo el mínimo | B48: 3 | C48: 1 | D48: 10 | E48: 3 | F48: 4 | G48: 1
...

Sheet Costos Fases
A2: SIGLA | B2: ROL | C2: NOMBRE | D2: VALOR HORA HH | E2: HORAS | F2: FASE PLANIFICACION | H2: COSTO POR HORA
A3: JP | B3: Jefe de Proyecto | C3: Melisa Quezada | D3: =$J$4 -> 11389 | E3: =SUM(EDT!C6:C9) -> 38 | F3: =D3*E3 -> 432782 | H3: ROL | I3: NOMBRE | J3: COSTO x HORA | K3: Sueldo mes
A4: AP | B4: Analista Programador | C4: Erick Paredes / Daniel Lizama | D4: =$J$5 -> 7778 | E4: =SUM(EDT!D6:D9) -> 17 | F4: =D4*E4 -> 132226 | H4: Jefe de Proyecto | I4: Melisa Quezada | J4: =ROUND(K4/$I$10,0) -> 11389 | K4: 2050000
A5: DBA | B5: Desarrollador BD | C5: José Miguel Ruíz | D5: =$J$6 -> 8056 | E5: =SUM(EDT!E6:E9) -> 9 | F5: =D5*E5 -> 72504 | H5: Analista Programador | I5: Erick Paredes / Daniel Lizama | J5: =ROUND(K5/$I$10,0) -> 7778 | K5: 1400000
A6: QA | B6: Calidad Y Testing | C6: Cristian Bernal | D6: =$J$7 -> 7778 | E6: =SUM(EDT!F6:F9) -> 11 | F6: =D6*E6 -> 85558 | H6: Administrador BD | I6: José Miguel Ruíz | J6: =ROUND(K6/$I$10,0) -> 8056 | K6: 1450000
A7: DI | B7: Diseñador | C7: Fernanda Aliaga | D7: =$J$8 -> 8333 | E7: =SUM(EDT!G6:G9) -> 9 | F7: =D7*E7 -> 74997 | H7: Calidad Y Testing | I7: Cristian Bernal | J7: =ROUND(K7/$I$10,0) -> 7778 | K7: 1400000
B8: TOTAL FASE PLANIFICACION | F8: =SUM(F3:F7) -> 798067 | H8: Diseñador | I8: Fernanda Aliaga | J8: =ROUND(K8/$I$10,0) -> 8333 | K8: 1500000
H9: Fuente sueldos: mercado TI Chile 2026 (IT Workers / Indeed)
H10: Horas mes (jornada legal 42 h/sem, Ley 21.561) | I10: 180
A11: SIGLA | B11: ROL | C11: NOMBRE | D11: VALOR HORA HH | E11: HORAS | F11: FASE DISEÑO | H11: COSTO HH POR ROL
A12: JP | B12: Jefe de Proyecto | C12: Melisa Quezada | D12: =$J$4 -> 11389 | E12: =SUM(EDT!C12:C16) -> 52 | F12: =D12*E12 -> 592228 | H12: Jefe de Proyecto | I12: =F3+F12+F21+F30+F39 -> 1708350
A13: AP | B13: Analista Programador | C13: Erick Paredes / Daniel Lizama | D13: =$J$5 -> 7778 | E13: =SUM(EDT!D12:D16) -> 70 | F13: =D13*E13 -> 544460 | H13: Analista Programador | I13: =F4+F13+F22+F31+F40 -> 4379014
A14: DBA | B14: Desarrollador BD | C14: José Miguel Ruíz | D14: =$J$6 -> 8056 | E14: =SUM(EDT!E12:E16) -> 50 | F14: =D14*E14 -> 402800 | H14: Administrador BD | I14: =F5+F14+F23+F32+F41 -> 2118728
A15: QA | B15: Calidad Y Testing | C15: Cristian Bernal | D15: =$J$7 -> 7778 | E15: =SUM(EDT!F12:F16) -> 38 | F15: =D15*E15 -> 295564 | H15: Calidad Y Testing | I15: =F6+F15+F24+F33+F42 -> 2535628
A16: DI | B16: Diseñador | C16: Fernanda Aliaga | D16: =$J$8 -> 8333 | E16: =SUM(EDT!G12:G16) -> 16 | F16: =D16*E16 -> 133328 | H16: Diseñador | I16: =F7+F16+F25+F34+F43 -> 1041625
B17: TOTAL FASE DISEÑO | F17: =SUM(F12:F16) -> 1968380 | H17: TOTAL HH | I17: =SUM(I12:I16) -> 11783345
A20: SIGLA | B20: ROL | C20: NOMBRE | D20: VALOR HORA HH | E20: HORAS | F20: FASE DESARROLLO | H20: COSTO POR FASE
A21: JP | B21: Jefe de Proyecto | C21: Melisa Quezada | D21: =$J$4 -> 11389 | E21: =SUM(EDT!C19:C60) -> 34 | F21: =D21*E21 -> 387226 | H21: Fase de Planificación | I21: =F8 -> 798067
A22: AP | B22: Analista Programador | C22: Erick Paredes / Daniel Lizama | D22: =$J$5 -> 7778 | E22: =SUM(EDT!D19:D60) -> 446 | F22: =D22*E22 -> 3468988 | H22: Fase de Análisis y Diseño | I22: =F17 -> 1968380
A23: DBA | B23: Desarrollador BD | C23: José Miguel Ruíz | D23: =$J$6 -> 8056 | E23: =SUM(EDT!E19:E60) -> 166 | F23: =D23*E23 -> 1337296 | H23: Fase de Desarrollo | I23: =F26 -> 7039068
A24: QA | B24: Calidad Y Testing | C24: Cristian Bernal | D24: =$J$7 -> 7778 | E24: =SUM(EDT!F19:F60) -> 143 | F24: =D24*E24 -> 1112254 | H24: Fase de QA | I24: =F35 -> 1094480
A25: DI | B25: Diseñador | C25: Fernanda Aliaga | D25: =$J$8 -> 8333 | E25: =SUM(EDT!G19:G60) -> 88 | F25: =D25*E25 -> 733304 | H25: Fase de Implementación y Cierre | I25: =F44 -> 883350
B26: TOTAL FASE DESARROLLO | F26: =SUM(F21:F25) -> 7039068 | H26: TOTAL HH FASES | I26: =SUM(I21:I25) -> 11783345
A29: SIGLA | B29: ROL | C29: NOMBRE | D29: VALOR HORA HH | E29: HORAS | F29: FASE PRUEBAS QA | H29: Margen | I29: 0.6
A30: JP | B30: Jefe de Proyecto | C30: Melisa Quezada | D30: =$J$4 -> 11389 | E30: =SUM(EDT!C64:C66) -> 0 | F30: =D30*E30 -> 0 | H30: UTILIDAD | I30: =I26*I29 -> 7070007
A31: AP | B31: Analista Programador | C31: Erick Paredes / Daniel Lizama | D31: =$J$5 -> 7778 | E31: =SUM(EDT!D64:D66) -> 0 | F31: =D31*E31 -> 0 | H31: PRECIO FINAL | I31: =I26+I30 -> 18853352
A32: DBA | B32: Desarrollador BD | C32: José Miguel Ruíz | D32: =$J$6 -> 8056 | E32: =SUM(EDT!E64:E66) -> 20 | F32: =D32*E32 -> 161120
A33: QA | B33: Calidad Y Testing | C33: Cristian Bernal | D33: =$J$7 -> 7778 | E33: =SUM(EDT!F64:F66) -> 120 | F33: =D33*E33 -> 933360
A34: DI | B34: Diseñador | C34: Fernanda Aliaga | D34: =$J$8 -> 8333 | E34: =SUM(EDT!G64:G66) -> 0 | F34: =D34*E34 -> 0
B35: TOTAL FASE PRUEBAS QA | F35: =SUM(F30:F34) -> 1094480
A38: SIGLA | B38: ROL | C38: NOMBRE | D38: VALOR HORA HH | E38: HORAS | F38: FASE IMPLEMENTACION Y CIERRE
A39: JP | B39: Jefe de Proyecto | C39: Melisa Quezada | D39: =$J$4 -> 11389 | E39: =SUM(EDT!C69:C72) -> 26 | F39: =D39*E39 -> 296114
A40: AP | B40: Analista Programador | C40: Erick Paredes / Daniel Lizama | D40: =$J$5 -> 7778 | E40: =SUM(EDT!D69:D72) -> 30 | F40: =D40*E40 -> 233340
A41: DBA | B41: Desarrollador BD | C41: José Miguel Ruíz | D41: =$J$6 -> 8056 | E41: =SUM(EDT!E69:E72) -> 18 | F41: =D41*E41 -> 145008
A42: QA | B42: Calidad Y Testing | C42: Cristian Bernal | D42: =$J$7 -> 7778 | E42: =SUM(EDT!F69:F72) -> 14 | F42: =D42*E42 -> 108892
A43: DI | B43: Diseñador | C43: Fernanda Aliaga | D43: =$J$8 -> 8333 | E43: =SUM(EDT!G69:G72) -> 12 | F43: =D43*E43 -> 99996
B44: TOTAL FASE IMPLEMENTACION | F44: =SUM(F39:F43) -> 883350
